Workbook

Sheet Introduction
A1: Introduction and Purpose
A2: This document is intended to rank starting Pokemon options in Roguemon by type using specified criteria.
A3: Everything in this document is my opinion. None of it is objective fact. Some of this is going to be colored by personal experience. Some of it might be internally inconsistent, and I'm fine with that. This is a hobby project, not my job. However, if you really think I've done something egregious that needs calling out, DM me on Discord (ZogaOak on the Roguemon Discord).
A4: Use this as a guideline, not as a be-all end-all of which mon is best. I rank Basculin above Tentacool, but not every Basculin is going to be better than every Tentacool.
A6: Things I took into account when ranking Pokemon:
A7: The Pokemon's starting BST, which influences the possibility of getting through early game and provides a more consistent look at the final spread of the Pokemon than a lower BST does. This is aimed towards A3 and takes into account whether a Pokemon is likely to survive long enough to evolve.
A8: Evolution method. Level-based is easiest to analyze. Friendship can sometimes be very easy and sometimes very difficult. Roguestone is the hardest method and the only one that may require a sacrifice, though it can be skill-testing to know when you need to upgrade and when you can afford to wait.
A9: The number of moves a mon gains between Level 9 and the point where it evolves (or, in the case of Roguestone or Friendship, where I feel it's most likely to evolve - this can be wrong). For the purposes of this guide, I assume that all mons are caught at level 8.
A10: The BST the mon would normally evolve into. In Roguemon, evolutions are randomly chosen from a possible pool which consists of Target BST +/- 10%. Mons that target 410 are very likely to evolve again into a higher BST mon. Mons that target 450 are likely to not evolve into anything great.
A11: The mon's secondary type. In addition to vulnerabilities and weaknesses, this also effects the mon's possible evolution. Even if a typing gives you more vulnerabilities (like Archen) or gives you a 4x weakness (like Amaura), it can be worth it to have the chance to evolve into a mon of a different typing. Not every type is equal.
A13: Disclaimer
A14: A ranking or tier-based system for a luck-based game is going to be imperfect. A higher ranking does not mean a mon is better. Use this as a guide - if you have a Kubfu that's about as strong as a Crabrawler, the Kubfu is going to end up better on average. Low-ranking mons have beaten A2 - showcased by the Tyrogue community event - and A3.
... A21: Full rules are available at roguemon.gg

Sheet Comparison
A1: Type | B1: Average BST | C1: Average Rating | D1: Roguestone%
A2: Fire | B2: =Fire!K2 -> 318.64 | C2: =Fire!K3 -> 6.44 | D2: =Fire!K5 -> 0.2
A3: Dragon | B3: =Dragon!K2 -> 298.08333 | C3: =Dragon!K3 -> 5.25 | D3: =Dragon!K5 -> 0.083333333
A4: Rock | B4: =Rock!K2 -> 334.66667 | C4: =Rock!K3 -> 5.1111111 | D4: =Rock!K5 -> 0.11111111
A5: Dark | B5: =Dark!K2 -> 319.3913 | C5: =Dark!K3 -> 5.0434783 | D5: =Dark!K5 -> 0.086956522
A6: Water | B6: =Water!K2 -> 309.23729 | C6: =Water!K3 -> 4.7118644 | D6: =Water!K5 -> 0.084745763
A7: Grass | B7: =Grass!K2 -> 298.13333 | C7: =Grass!K3 -> 4.5333333 | D7: =Grass!K5 -> 0.22222222
A8: Poison | B8: =Poison!K2 -> 308.18182 | C8: =Poison!K3 -> 4.5151515 | D8: =Poison!K5 -> 0.03030303
A9: Ghost | B9: =Ghost!K2 -> 320.08696 | C9: =Ghost!K3 -> 4.4347826 | D9: =Ghost!K5 -> 0.2173913
A10: Fighting | B10: =Fighting!K2 -> 320.58824 | C10: =Fighting!K3 -> 4.3529412 | D10: =Fighting!K5 -> 0.17647059
A11: Electric | B11: =Electric!K2 -> 307.47826 | C11: =Electric!K3 -> 4.3478261 | D11: =Electric!K5 -> 0.13043478
A12: Flying | B12: =Flying!K2 -> 303.0625 | C12: =Flying!K3 -> 4.21875 | D12: =Flying!K5 -> 0.0625
A13: Normal | B13: =Normal!K2 -> 296.36364 | C13: =Normal!K3 -> 4.1818182 | D13: =Normal!K5 -> 0.090909091
A14: Psychic | B14: =Psychic!K2 -> 306.03448 | C14: =Psychic!K3 -> 4.0689655 | D14: =Psychic!K5 -> 0.10344828
A15: Ice | B15: =Ice!K2 -> 309.88235 | C15: =Ice!K3 -> 4.0588235 | D15: =Ice!K5 -> 0.29411765
A16: Steel | B16: =Steel!K2 -> 314.05882 | C16: =Steel!K3 -> 3.6470588 | D16: =Steel!K5 -> 0.058823529
A17: Fairy | B17: =Fairy!K2 -> 280.5 | C17: =Fairy!K3 -> 3.6111111 | D17: =Fairy!K5 -> 0.22222222
A18: Ground | B18: =Ground!K2 -> 305 | C18: =Ground!K3 -> 3.5357143 | D18: =Ground!K5 -> 0.071428571
A19: Bug | B19: =Bug!K2 -> 267.61765 | C19: =Bug!K3 -> 2.9705882 | D19: =Bug!K5 -> 0.058823529

Sheet Bug
A1: ! | B1: Pokemon | C1: BST | D1: Evo method | E1: Target BST | F1: Moves 9 to Evo | G1: Alt Type | H1: Rating | I1: Ranking | J1: Number of mons | K1: 34
A2: =IFNA(VLOOKUP(B2,Sprites!$A$2:$B$1200,2,FALSE),"") | B2: Larvesta | C2: 360 | D2: Level 40 | E2: 550 | F2: 5 | G2: Fire | H2: 8 | I2: 1 | J2: Average BST | K2: =SUM(C2:C1000)/K1 -> 267.61765
A3: =IFNA(VLOOKUP(B3,Sprites!$A$2:$B$1200,2,FALSE),"") | B3: Yanma | C3: 390 | D3: Level 33 | E3: 515 | F3: 7 | G3: Flying | H3: 7 | I3: 2 | J3: Average Rating | K3: =SUM(H2:H1000)/K1 -> 2.9705882
A4: =IFNA(VLOOKUP(B4,Sprites!$A$2:$B$1200,2,FALSE),"") | B4: Sizzlipede | C4: 305 | D4: Level 28 | E4: 525 | F4: 4 | G4: Fire | H4: 6 | I4: 3 | J4: Roguestone # | K4: =COUNTIF(D2:D1000, "Roguestone") -> 2
A5: =IFNA(VLOOKUP(B5,Sprites!$A$2:$B$1200,2,FALSE),"") | B5: Skorupi | C5: 330 | D5: Level 40 | E5: 500 | F5: 11 | G5: Poison | H5: 5 | I5: 4 | J5: Roguestone % | K5: =K4/K1 -> 0.058823529
A6: =IFNA(VLOOKUP(B6,Sprites!$A$2:$B$1200,2,FALSE),"") | B6: Anorith | C6: 355 | D6: Level 40 | E6: 495 | F6: 7 | G6: Rock | H6: 5 | I6: 5
A7: =IFNA(VLOOKUP(B7,Sprites!$A$2:$B$1200,2,FALSE),"") | B7: Ledyba | C7: 265 | D7: Level 18 | E7: 390 | F7: 4 | G7: Flying | H7: 5 | I7: 6
A8: =IFNA(VLOOKUP(B8,Sprites!$A$2:$B$1200,2,FALSE),"") | B8: Tarountula | C8: 210 | D8: Level 15 | E8: 404 | F8: 2 | H8: 4 | I8: 7
A9: =IFNA(VLOOKUP(B9,Sprites!$A$2:$B$1200,2,FALSE),"") | B9: Grubbin | C9: 300 | D9: Level 20 | E9: 420 | F9: 2 | H9: 4 | I9: 8
A10: =IFNA(VLOOKUP(B10,Sprites!$A$2:$B$1200,2,FALSE),"") | B10: Rellor | C10: 270 | D10: Friendship | E10: 470 | F10: 2 | H10: 4 | I10: 9
A11: =IFNA(VLOOKUP(B11,Sprites!$A$2:$B$1200,2,FALSE),"") | B11: Karrablast | C11: 315 | D11: Roguestone | E11: 495 | F11: 7 | H11: 4 | I11: 10
A12: =IFNA(VLOOKUP(B12,Sprites!$A$2:$B$1200,2,FALSE),"") | B12: Shelmet | C12: 305 | D12: Roguestone | E12: 495 | F12: 6 | H12: 4 | I12: 11
A13: =IFNA(VLOOKUP(B13,Sprites!$A$2:$B$1200,2,FALSE),"") | B13: Burmy | C13: 224 | D13: Level 20 | E13: 424 | F13: 3 | H13: 3 | I13: 12
A14: =IFNA(VLOOKUP(B14,Sprites!$A$2:$B$1200,2,FALSE),"") | B14: Spinarak | C14: 269 | D14: Level 22 | E14: 390 | F14: 4 | G14: Poison | H14: 3 | I14: 13
A15: =IFNA(VLOOKUP(B15,Sprites!$A$2:$B$1200,2,FALSE),"") | B15: Dwebble | C15: 325 | D15: Level 34 | E15: 475 | F15: 6 | G15: Rock | H15: 3 | I15: 14
A16: =IFNA(VLOOKUP(B16,Sprites!$A$2:$B$1200,2,FALSE),"") | B16: Cutiefly | C16: 304 | D16: Level 25 | E16: 464 | F16: 3 | G16: Fairy | H16: 3 | I16: 15
A17: =IFNA(VLOOKUP(B17,Sprites!$A$2:$B$1200,2,FALSE),"") | B17: Venipede | C17: 305 | D17: Level 22 | E17: 360 | F17: 3 | G17: Poison | H17: 3 | I17: 16
A18: =IFNA(VLOOKUP(B18,Sprites!$A$2:$B$1200,2,FALSE),"") | B18: Venonat | C18: 305 | D18: Level 31 | E18: 450 | F18: 6 | G18: Poison | H18: 3 | I18: 17
A19: =IFNA(VLOOKUP(B19,Sprites!$A$2:$B$1200,2,FALSE),"") | B19: Joltik | C19: 319 | D19: Level 36 | E19: 472 | F19: 6 | G19: Electric | H19: 2 | I19: 18
A20: =IFNA(VLOOKUP(B20,Sprites!$A$2:$B$1200,2,FALSE),"") | B20: Kricketot | C20: 194 | D20: Level 10 | E20: 384 | F20: 0 | H20: 2 | I20: 19
A21: =IFNA(VLOOKUP(B21,Sprites!$A$2:$B$1200,2,FALSE),"") | B21: Blipbug | C21: 180 | D21: Level 10 | E21: 335 | F21: 0 | H21: 2 | I21: 20
A22: =IFNA(VLOOKUP(B22,Sprites!$A$2:$B$1200,2,FALSE),"") | B22: Paras | C22: 285 | D22: Level 24 | E22: 405 | F22: 3 | G22: Grass | H22: 2 | I22: 21
A23: =IFNA(VLOOKUP(B23,Sprites!$A$2:$B$1200,2,FALSE),"") | B23: Sewaddle | C23: 310 | D23: Level 20 | E23: 380 | F23: 1 | G23: Grass | H23: 2 | I23: 22
A24: =IFNA(VLOOKUP(B24,Sprites!$A$2:$B$1200,2,FALSE),"") | B24: Wimpod | C24: 230 | D24: Level 30 | E24: 530 | F24: 0 | G24: Water | H24: 2 | I24: 23
A25: =IFNA(VLOOKUP(B25,Sprites!$A$2:$B$1200,2,FALSE),"") | B25: Nincada | C25: 266 | D25: Level 20 | E25: 456/256 | F25: 2 | G25: Ground | H25: 2 | I25: 24
A26: =IFNA(VLOOKUP(B26,Sprites!$A$2:$B$1200,2,FALSE),"") | B26: Combee | C26: 244 | D26: Level 21 | E26: 474 | F26: 0 | G26: Flying | H26: 2 | I26: 25
A27: =IFNA(VLOOKUP(B27,Sprites!$A$2:$B$1200,2,FALSE),"") | B27: Pineco | C27: 290 | D27: Level 31 | E27: 465 | F27: 7 | H27: 2 | I27: 26
A28: =IFNA(VLOOKUP(B28,Sprites!$A$2:$B$1200,2,FALSE),"") | B28: Nymble | C28: 210 | D28: Level 24 | E28: 450 | F28: 5 | H28: 2 | I28: 27
A29: =IFNA(VLOOKUP(B29,Sprites!$A$2:$B$1200,2,FALSE),"") | B29: Snom | C29: 185 | D29: Friendship | E29: 475 | F29: 0 | G29: Ice | H29: 1 | I29: 28
A30: =IFNA(VLOOKUP(B30,Sprites!$A$2:$B$1200,2,FALSE),"") | B30: Scatterbug | C30: 185 | D30: Level 9 | E30: 213 | F30: 0 | H30: 1 | I30: 29
A31: =IFNA(VLOOKUP(B31,Sprites!$A$2:$B$1200,2,FALSE),"") | B31: Dewpider | C31: 269 | D31: Level 22 | E31: 454 | F31: 3 | G31: Water | H31: 1 | I31: 30
A32: =IFNA(VLOOKUP(B32,Sprites!$A$2:$B$1200,2,FALSE),"") | B32: Surskit | C32: 210 | D32: Level 22 | E32: 454 | F32: 4 | G32: Water | H32: 1 | I32: 31
A33: =IFNA(VLOOKUP(B33,Sprites!$A$2:$B$1200,2,FALSE),"") | B33: Weedle | C33: 195 | D33: Level 7 | E33: 205 | F33: 1 | G33: Poison | H33: 1 | I33: 32
A34: =IFNA(VLOOKUP(B34,Sprites!$A$2:$B$1200,2,FALSE),"") | B34: Caterpie | C34: 195 | D34: Level 7 | E34: 205 | F34: 0 | H34: 1 | I34: 33
A35: =IFNA(VLOOKUP(B35,Sprites!$A$2:$B$1200,2,FALSE),"") | B35: Wurmple | C35: 195 | D35: Level 7 | E35: 205 | F35: 0 | H35: 1 | I35: 34
A36: =IFNA(VLOOKUP(B36,Sprites!$A$2:$B$1200,2,FALSE),"")
A37: =IFNA(VLOOKUP(B37,Sprites!$A$2:$B$1200,2,FALSE),"")
A38: =IFNA(VLOOKUP(B38,Sprites!$A$2:$B$1200,2,FALSE),"")
A39: =IFNA(VLOOKUP(B39,Sprites!$A$2:$B$1200,2,FALSE),"")
A40: =IFNA(VLOOKUP(B40,Sprites!$A$2:$B$1200,2,FALSE),"")
...

Sheet Dark
A1: Qwi | B1: Pokemon | C1: BST | D1: Evo method | E1: Target BST | F1: Moves 9 to Evo | G1: Alt Type | H1: Rating | I1: Ranking | J1: Number of mons | K1: 23
A2: =IFNA(VLOOKUP(B2,Sprites!$A$2:$B$1200,2,FALSE),"") | B2: Qwilfish H | C2: 440 | D2: Level 28 | E2: 510 | F2: 5 | G2: Poison | H2: 9 | I2: 1 | J2: Average BST | K2: =SUM(C2:C999)/K1 -> 319.3913
A3: =IFNA(VLOOKUP(B3,Sprites!$A$2:$B$1200,2,FALSE),"") | B3: Sneasel | C3: 430 | D3: Roguestone | E3: 510 | F3: 7 | G3: Ice | H3: 7 | I3: 2 | J3: Average Rating | K3: =SUM(H2:H999)/K1 -> 5.0434783
A4: =IFNA(VLOOKUP(B4,Sprites!$A$2:$B$1200,2,FALSE),"") | B4: Zorua | C4: 330 | D4: Level 30 | E4: 510 | F4: 5 | H4: 7 | I4: 3 | J4: Roguestone # | K4: =COUNTIF(D2:D999, "Roguestone") -> 2
A5: =IFNA(VLOOKUP(B5,Sprites!$A$2:$B$1200,2,FALSE),"") | B5: Murkrow | C5: 405 | D5: Roguestone | E5: 505 | F5: 7 | G5: Flying | H5: 7 | I5: 4 | J5: Roguestone % | K5: =K4/K1 -> 0.086956522
A6: =IFNA(VLOOKUP(B6,Sprites!$A$2:$B$1200,2,FALSE),"") | B6: Houndour | C6: 330 | D6: Level 24 | E6: 500 | F6: 3 | G6: Fire | H6: 7 | I6: 5
A7: =IFNA(VLOOKUP(B7,Sprites!$A$2:$B$1200,2,FALSE),"") | B7: Sableye | C7: 380 | D7: BST/10 | E7: 480 | F7: 14 | G7: Ghost | H7: 6 | I7: 6
A8: =IFNA(VLOOKUP(B8,Sprites!$A$2:$B$1200,2,FALSE),"") | B8: Vullaby | C8: 370 | D8: Level 42 | E8: 510 | F8: 6 | G8: Flying | H8: 6 | I8: 7
A9: =IFNA(VLOOKUP(B9,Sprites!$A$2:$B$1200,2,FALSE),"") | B9: Deino | C9: 300 | D9: Level 35 | E9: 420 | F9: 6 | G9: Dragon | H9: 6 | I9: 8
A10: =IFNA(VLOOKUP(B10,Sprites!$A$2:$B$1200,2,FALSE),"") | B10: Maschiff | C10: 340 | D10: Level 30 | E10: 505 | F10: 5 | H10: 6 | I10: 9
A11: =IFNA(VLOOKUP(B11,Sprites!$A$2:$B$1200,2,FALSE),"") | B11: Grimer A | C11: 325 | D11: Level 38 | E11: 500 | F11: 8 | G11: Poison | H11: 5 | I11: 10
A12: =IFNA(VLOOKUP(B12,Sprites!$A$2:$B$1200,2,FALSE),"") | B12: Stunky | C12: 329 | D12: Level 34 | E12: 479 | F12: 9 | G12: Poison | H12: 5 | I12: 11
A13: =IFNA(VLOOKUP(B13,Sprites!$A$2:$B$1200,2,FALSE),"") | B13: Rattata A | C13: 253 | D13: Level 20 | E13: 413 | F13: 4 | G13: Normal | H13: 5 | I13: 12
A14: =IFNA(VLOOKUP(B14,Sprites!$A$2:$B$1200,2,FALSE),"") | B14: Poochyena | C14: 220 | D14: Level 18 | E14: 420 | F14: 3 | H14: 5 | I14: 13
A15: =IFNA(VLOOKUP(B15,Sprites!$A$2:$B$1200,2,FALSE),"") | B15: Zigzagoon G | C15: 240 | D15: Level 20 | E15: 420 | F15: 4 | G15: Normal | H15: 4 | I15: 14
A16: =IFNA(VLOOKUP(B16,Sprites!$A$2:$B$1200,2,FALSE),"") | B16: Meowth A | C16: 290 | D16: Friendship | E16: 440 | F16: 3 | H16: 4 | I16: 15
A17: =IFNA(VLOOKUP(B17,Sprites!$A$2:$B$1200,2,FALSE),"") | B17: Pawniard | C17: 340 | D17: Level 30 | E17: 490 | F17: 5 | G17: Steel | H17: 4 | I17: 16
A18: =IFNA(VLOOKUP(B18,Sprites!$A$2:$B$1200,2,FALSE),"") | B18: Nickit | C18: 245 | D18: Level 18 | E18: 455 | F18: 2 | H18: 4 | I18: 17
A19: =IFNA(VLOOKUP(B19,Sprites!$A$2:$B$1200,2,FALSE),"") | B19: Inkay | C19: 288 | D19: Level 30 | E19: 482 | F19: 7 | G19: Psychic | H19: 4 | I19: 18
A20: =IFNA(VLOOKUP(B20,Sprites!$A$2:$B$1200,2,FALSE),"") | B20: Carvanha | C20: 305 | D20: Level 30 | E20: 460 | F20: 5 | G20: Water | H20: 4 | I20: 19
A21: =IFNA(VLOOKUP(B21,Sprites!$A$2:$B$1200,2,FALSE),"") | B21: Impidimp | C21: 265 | D21: Level 32 | E21: 370 | F21: 5 | G21: Fairy | H21: 3 | I21: 20
A22: =IFNA(VLOOKUP(B22,Sprites!$A$2:$B$1200,2,FALSE),"") | B22: Scraggy | C22: 348 | D22: Level 39 | E22: 488 | F22: 7 | G22: Fighting | H22: 3 | I22: 21
A23: =IFNA(VLOOKUP(B23,Sprites!$A$2:$B$1200,2,FALSE),"") | B23: Sandile | C23: 292 | D23: Level 29 | E23: 351 | F23: 7 | G23: Ground | H23: 3 | I23: 22
A24: =IFNA(VLOOKUP(B24,Sprites!$A$2:$B$1200,2,FALSE),"") | B24: Purrloin | C24: 281 | D24: Level 20 | E24: 446 | F24: 2 | H24: 2 | I24: 23
B26: Date | C26: Change
B27: 46001 | C27: Bumped Meowth A from 2 (rank 22) to 4 (rank 15). It evolves early and can evolve again. Will keep an eye on this, might move it up further.
B29: 46001 | C29: Sneasel moved down to rating 7.

Sheet Dragon
A1: ! | B1: Pokemon | C1: BST | D1: Evo method | E1: Target BST | F1: Moves 9 to Evo | G1: Alt Type | H1: Rating | I1: Ranking | J1: Number of mons | K1: 12
A2: =IFNA(VLOOKUP(B2,Sprites!$A$2:$B$1200,2,FALSE),"") | B2: Bagon | C2: 300 | D2: Level 30 | E2: 420 | F2: 4 | H2: 7 | I2: 1 | J2: Average BST | K2: =SUM(C2:C1001)/K1 -> 298.08333
A3: =IFNA(VLOOKUP(B3,Sprites!$A$2:$B$1200,2,FALSE),"") | B3: Dratini | C3: 300 | D3: Level 30 | E3: 420 | F3: 4 | H3: 7 | I3: 2 | J3: Average Rating | K3: =SUM(H2:H1001)/K1 -> 5.25
A4: =IFNA(VLOOKUP(B4,Sprites!$A$2:$B$1200,2,FALSE),"") | B4: Tyrunt | C4: 362 | D4: Level 39 | E4: 521 | F4: 7 | G4: Rock | H4: 7 | I4: 3 | J4: Roguestone # | K4: =COUNTIF(D2:D1000, "Roguestone") -> 1
A5: =IFNA(VLOOKUP(B5,Sprites!$A$2:$B$1200,2,FALSE),"") | B5: Gible | C5: 300 | D5: Level 24 | E5: 410 | F5: 2 | G5: Ground | H5: 7 | I5: 4 | J5: Roguestone % | K5: =K4/K1 -> 0.083333333
A6: =IFNA(VLOOKUP(B6,Sprites!$A$2:$B$1200,2,FALSE),"") | B6: Jangmo-O | C6: 300 | D6: Level 35 | E6: 420 | F6: 6 | H6: 6 | I6: 5
A7: =IFNA(VLOOKUP(B7,Sprites!$A$2:$B$1200,2,FALSE),"") | B7: Axew | C7: 320 | D7: Level 38 | E7: 410 | F7: 11 | H7: 6 | I7: 6
A8: =IFNA(VLOOKUP(B8,Sprites!$A$2:$B$1200,2,FALSE),"") | B8: Deino | C8: 300 | D8: Level 35 | E8: 420 | F8: 6 | G8: Dark | H8: 5 | I8: 7
A9: =IFNA(VLOOKUP(B9,Sprites!$A$2:$B$1200,2,FALSE),"") | B9: Frigibax | C9: 320 | D9: Level 35 | E9: 423 | F9: 5 | G9: Ice | H9: 5 | I9: 8
A10: =IFNA(VLOOKUP(B10,Sprites!$A$2:$B$1200,2,FALSE),"") | B10: Goomy | C10: 300 | D10: Level 40 | E10: 420 | F10: 7 | H10: 4 | I10: 9
A11: =IFNA(VLOOKUP(B11,Sprites!$A$2:$B$1200,2,FALSE),"") | B11: Dreepy | C11: 270 | D11: Level 30 | E11: 410 | F11: 0 | G11: Ghost | H11: 4 | I11: 10
A12: =IFNA(VLOOKUP(B12,Sprites!$A$2:$B$1200,2,FALSE),"") | B12: Noibat | C12: 245 | D12: Level 32 | E12: 535 | F12: 6 | G12: Flying | H12: 3 | I12: 11
A13: =IFNA(VLOOKUP(B13,Sprites!$A$2:$B$1200,2,FALSE),"") | B13: Applin | C13: 260 | D13: Roguestone | E13: 485 | F13: 0 | G13: Grass | H13: 2 | I13: 12
A14: =IFNA(VLOOKUP(B14,Sprites!$A$2:$B$1200,2,FALSE),"")
A15: =IFNA(VLOOKUP(B15,Sprites!$A$2:$B$1200,2,FALSE),"") | B15: Date | C15: Change
A16: =IFNA(VLOOKUP(B16,Sprites!$A$2:$B$1200,2,FALSE),"") | B16: 46001 | C16: Axew from Rank 5 to 6 (Learns 11 moves, but it's still 320 BST that evolves after Misty), Goomy dropped to Rating 4 Ranking 9 (it's pure dragon, but it evolves at level 40, compared to Deino and Frigibax which have weaker typings but evolve before Misty).
A17: =IFNA(VLOOKUP(B17,Sprites!$A$2:$B$1200,2,FALSE),"")
A18: =IFNA(VLOOKUP(B18,Sprites!$A$2:$B$1200,2,FALSE),"")
A19: =IFNA(VLOOKUP(B19,Sprites!$A$2:$B$1200,2,FALSE),"")
A20: =IFNA(VLOOKUP(B20,Sprites!$A$2:$B$1200,2,FALSE),"")
A21: =IFNA(VLOOKUP(B21,Sprites!$A$2:$B$1200,2,FALSE),"")
A22: =IFNA(VLOOKUP(B22,Sprites!$A$2:$B$1200,2,FALSE),"")
A23: =IFNA(VLOOKUP(B23,Sprites!$A$2:$B$1200,2,FALSE),"")
A24: =IFNA(VLOOKUP(B24,Sprites!$A$2:$B$1200,2,FALSE),"")
A25: =IFNA(VLOOKUP(B25,Sprites!$A$2:$B$1200,2,FALSE),"")
A26: =IFNA(VLOOKUP(B26,Sprites!$A$2:$B$1200,2,FALSE),"")
A27: =IFNA(VLOOKUP(B27,Sprites!$A$2:$B$1200,2,FALSE),"")
A28: =IFNA(VLOOKUP(B28,Sprites!$A$2:$B$1200,2,FALSE),"")
... A89: =IFNA(VLOOKUP(B89,Sprites!$A$2:$B$1200,2,FALSE),"")

Sheet Electric
A1: ! | B1: Pokemon | C1: BST | D1: Evo method | E1: Target BST | F1: Moves 9 to Evo | G1: Alt Type | H1: Rating | I1: Ranking | J1: Number of mons | K1: 23
A2: =IFNA(VLOOKUP(B2,Sprites!$A$2:$B$1200,2,FALSE),"") | B2: Plusle | C2: 405 | D2: BST/10 | E2: 505 | F2: 13 | H2: 7 | I2: 1 | J2: Average BST | K2: =SUM(C2:C1000)/K1 -> 307.47826
A3: =IFNA(VLOOKUP(B3,Sprites!$A$2:$B$1200,2,FALSE),"") | B3: Minun | C3: 405 | D3: BST/10 | E3: 505 | F3: 13 | H3: 7 | I3: 2 | J3: Average Rating | K3: =SUM(H2:H1000)/K1 -> 4.3478261
A4: =IFNA(VLOOKUP(B4,Sprites!$A$2:$B$1200,2,FALSE),"") | B4: Pachirisu | C4: 405 | D4: BST/10 | E4: 505 | F4: 12 | H4: 7 | I4: 3 | J4: Roguestone # | K4: =COUNTIF(D2:D1000, "Roguestone") -> 3
A5: =IFNA(VLOOKUP(B5,Sprites!$A$2:$B$1200,2,FALSE),"") | B5: Shinx | C5: 300 | D5: Level 15 | E5: 370 | F5: 1 | H5: 6 | I5: 4 | J5: Roguestone % | K5: =K4/K1 -> 0.13043478
A6: =IFNA(VLOOKUP(B6,Sprites!$A$2:$B$1200,2,FALSE),"") | B6: Elekid | C6: 360 | D6: Level 30 | E6: 490 | F6: 5 | H6: 6 | I6: 5
A7: =IFNA(VLOOKUP(B7,Sprites!$A$2:$B$1200,2,FALSE),"") | B7: Toxel | C7: 242 | D7: Level 19 | E7: 502 | F7: 0 | G7: Poison | H7: 5 | I7: 6
A8: =IFNA(VLOOKUP(B8,Sprites!$A$2:$B$1200,2,FALSE),"") | B8: Mareep | C8: 280 | D8: Level 15 | E8: 365 | F8: 2 | H8: 5 | I8: 7
A9: =IFNA(VLOOKUP(B9,Sprites!$A$2:$B$1200,2,FALSE),"") | B9: Blitzle | C9: 295 | D9: Level 27 | E9: 497 | F9: 5 | H9: 5 | I9: 8
A10: =IFNA(VLOOKUP(B10,Sprites!$A$2:$B$1200,2,FALSE),"") | B10: Voltorb | C10: 330 | D10: Level 30 | E10: 480 | F10: 8 | H10: 5 | I10: 9
A11: =IFNA(VLOOKUP(B11,Sprites!$A$2:$B$1200,2,FALSE),"") | B11: Wattrel | C11: 280 | D11: Level 25 | E11: 490 | F11: 4 | G11: Flying | H11: 5 | I11: 10
A12: =IFNA(VLOOKUP(B12,Sprites!$A$2:$B$1200,2,FALSE),"") | B12: Yamper | C12: 270 | D12: Level 25 | E12: 490 | F12: 3 | H12: 5 | I12: 11
A13: =IFNA(VLOOKUP(B13,Sprites!$A$2:$B$1200,2,FALSE),"") | B13: Geodude A | C13: 300 | D13: Level 25 | E13: 390 | F13: 5 | G13: Rock | H13: 4 | I13: 12
A14: =IFNA(VLOOKUP(B14,Sprites!$A$2:$B$1200,2,FALSE),"") | B14: Electrike | C14: 295 | D14: Level 26 | E14: 475 | F14: 4 | H14: 4 | I14: 13
A15: =IFNA(VLOOKUP(B15,Sprites!$A$2:$B$1200,2,FALSE),"") | B15: Voltorb H | C15: 330 | D15: Roguestone | E15: 480 | F15: 10 | G15: Grass | H15: 4 | I15: 14
A16: =IFNA(VLOOKUP(B16,Sprites!$A$2:$B$1200,2,FALSE),"") | B16: Helioptile | C16: 289 | D16: Roguestone | E16: 481 | F16: 6 | G16: Normal | H16: 4 | I16: 15
A17: =IFNA(VLOOKUP(B17,Sprites!$A$2:$B$1200,2,FALSE),"") | B17: Pawmi | C17: 240 | D17: Level 18 | E17: 350 | F17: 2 | H17: 3 | I17: 16
A18: =IFNA(VLOOKUP(B18,Sprites!$A$2:$B$1200,2,FALSE),"") | B18: Chinchou | C18: 330 | D18: Level 27 | E18: 460 | F18: 4 | H18: 3 | I18: 17
A19: =IFNA(VLOOKUP(B19,Sprites!$A$2:$B$1200,2,FALSE),"") | B19: Pikachu C | C19: 320 | D19: BST/10 | E19: 420 | F19: 8 | H19: 3 | I19: 18
A20: =IFNA(VLOOKUP(B20,Sprites!$A$2:$B$1200,2,FALSE),"") | B20: Tadbulb | C20: 272 | D20: Roguestone | E20: 495 | F20: 6 | H20: 3 | I20: 19
A21: =IFNA(VLOOKUP(B21,Sprites!$A$2:$B$1200,2,FALSE),"") | B21: Magnemite | C21: 325 | D21: Level 30 | E21: 465 | F21: 5 | G21: Steel | H21: 3 | I21: 20
A22: =IFNA(VLOOKUP(B22,Sprites!$A$2:$B$1200,2,FALSE),"") | B22: Joltik | C22: 319 | D22: Level 36 | E22: 472 | F22: 6 | G22: Bug | H22: 2 | I22: 21
A23: =IFNA(VLOOKUP(B23,Sprites!$A$2:$B$1200,2,FALSE),"") | B23: Pichu | C23: 205 | D23: Friendship | E23: 320 | F23: 2 | H23: 2 | I23: 22
A24: =IFNA(VLOOKUP(B24,Sprites!$A$2:$B$1200,2,FALSE),"") | B24: Tynamo | C24: 275 | D24: Level 21 | E24: 405 | F24: 0 | H24: 2 | I24: 23
A25: =IFNA(VLOOKUP(B25,Sprites!$A$2:$B$1200,2,FALSE),"")
A26: =IFNA(VLOOKUP(B26,Sprites!$A$2:$B$1200,2,FALSE),"") | B26: Date | C26: Change
A27: =IFNA(VLOOKUP(B27,Sprites!$A$2:$B$1200,2,FALSE),"") | B27: 46001 | C27: Shinx moved from Rating 5 Ranking 5 to Rating 6 Ranking 4. Moving Mareep up just below Toxel. Joltik down to a 2.
A28: =IFNA(VLOOKUP(B28,Sprites!$A$2:$B$1200,2,FALSE),"")
A29: =IFNA(VLOOKUP(B29,Sprites!$A$2:$B$1200,2,FALSE),"")
A30: =IFNA(VLOOKUP(B30,Sprites!$A$2:$B$1200,2,FALSE),"")
A31: =IFNA(VLOOKUP(B31,Sprites!$A$2:$B$1200,2,FALSE),"")
A32: =IFNA(VLOOKUP(B32,Sprites!$A$2:$B$1200,2,FALSE),"")
A33: =IFNA(VLOOKUP(B33,Sprites!$A$2:$B$1200,2,FALSE),"")
A34: =IFNA(VLOOKUP(B34,Sprites!$A$2:$B$1200,2,FALSE),"")
A35: =IFNA(VLOOKUP(B35,Sprites!$A$2:$B$1200,2,FALSE),"")
A36: =IFNA(VLOOKUP(B36,Sprites!$A$2:$B$1200,2,FALSE),"")
A37: =IFNA(VLOOKUP(B37,Sprites!$A$2:$B$1200,2,FALSE),"")
A38: =IFNA(VLOOKUP(B38,Sprites!$A$2:$B$1200,2,FALSE),"")
A39: =IFNA(VLOOKUP(B39,Sprites!$A$2:$B$1200,2,FALSE),"")
... A88: =IFNA(VLOOKUP(B88,Sprites!$A$2:$B$1200,2,FALSE),"")

Sheet Fairy
A1: ! | B1: Pokemon | C1: BST | D1: Evo method | E1: Target BST | F1: Moves 9 to Evo | G1: Alt Type | H1: Rating | I1: Ranking | J1: Number of mons | K1: 18
A2: =IFNA(VLOOKUP(B2,Sprites!$A$2:$B$1200,2,FALSE),"") | B2: Togepi | C2: 245 | D2: Friendship | E2: 405 | F2: 2 | H2: 6 | I2: 1 | J2: Average BST | K2: =SUM(C2:C1001)/K1 -> 280.5
A3: =IFNA(VLOOKUP(B3,Sprites!$A$2:$B$1200,2,FALSE),"") | B3: Tinkatink | C3: 297 | D3: Level 24 | E3: 380 | F3: 5 | G3: Steel | H3: 6 | I3: 2 | J3: Average Rating | K3: =SUM(H2:H1001)/K1 -> 3.6111111
A4: =IFNA(VLOOKUP(B4,Sprites!$A$2:$B$1200,2,FALSE),"") | B4: Mawile | C4: 380 | D4: BST/10 | E4: 480 | F4: 12 | G4: Steel | H4: 5 | I4: 3 | J4: Roguestone # | K4: =COUNTIF(D2:D1000, "Roguestone") -> 4
A5: =IFNA(VLOOKUP(B5,Sprites!$A$2:$B$1200,2,FALSE),"") | B5: Swirlix | C5: 341 | D5: Roguestone | E5: 480 | F5: 10 | H5: 5 | I5: 4 | J5: Roguestone % | K5: =K4/K1 -> 0.22222222
A6: =IFNA(VLOOKUP(B6,Sprites!$A$2:$B$1200,2,FALSE),"") | B6: Spritzee | C6: 341 | D6: Roguestone | E6: 462 | F6: 11 | H6: 5 | I6: 5
A7: =IFNA(VLOOKUP(B7,Sprites!$A$2:$B$1200,2,FALSE),"") | B7: Flabebe | C7: 303 | D7: Level 19 | E7: 371 | F7: 2 | H7: 5 | I7: 6
A8: =IFNA(VLOOKUP(B8,Sprites!$A$2:$B$1200,2,FALSE),"") | B8: Milcery | C8: 270 | D8: Roguestone | E8: 495 | F8: 5 | H8: 4 | I8: 7
A9: =IFNA(VLOOKUP(B9,Sprites!$A$2:$B$1200,2,FALSE),"") | B9: Mime Jr | C9: 310 | D9: Level 15 | E9: 460 | F9: 1 | G9: Psychic | H9: 4 | I9: 8
A10: =IFNA(VLOOKUP(B10,Sprites!$A$2:$B$1200,2,FALSE),"") | B10: Fidough | C10: 312 | D10: Level 26 | E10: 477 | F10: 5 | H10: 4 | I10: 9
A11: =IFNA(VLOOKUP(B11,Sprites!$A$2:$B$1200,2,FALSE),"") | B11: Snubbull | C11: 300 | D11: Level 23 | E11: 450 | F11: 2 | H11: 4 | I11: 10
A12: =IFNA(VLOOKUP(B12,Sprites!$A$2:$B$1200,2,FALSE),"") | B12: Cutiefly | C12: 304 | D12: Level 25 | E12: 464 | F12: 3 | G12: Bug | H12: 3 | I12: 11
A13: =IFNA(VLOOKUP(B13,Sprites!$A$2:$B$1200,2,FALSE),"") | B13: Morelull | C13: 285 | D13: Level 24 | E13: 405 | F13: 3 | G13: Grass | H13: 3 | I13: 12
A14: =IFNA(VLOOKUP(B14,Sprites!$A$2:$B$1200,2,FALSE),"") | B14: Cottonee | C14: 280 | D14: Roguestone | E14: 480 | F14: 9 | G14: Grass | H14: 3 | I14: 13
A15: =IFNA(VLOOKUP(B15,Sprites!$A$2:$B$1200,2,FALSE),"") | B15: Impidimp | C15: 265 | D15: Level 32 | E15: 370 | F15: 5 | G15: Dark | H15: 3 | I15: 14
A16: =IFNA(VLOOKUP(B16,Sprites!$A$2:$B$1200,2,FALSE),"") | B16: Cleffa | C16: 218 | D16: Friendship | E16: 323 | F16: 2 | H16: 2 | I16: 15
A17: =IFNA(VLOOKUP(B17,Sprites!$A$2:$B$1200,2,FALSE),"") | B17: Igglybuff | C17: 210 | D17: Friendship | E17: 270 | F17: 2 | G17: Normal | H17: 1 | I17: 16
A18: =IFNA(VLOOKUP(B18,Sprites!$A$2:$B$1200,2,FALSE),"") | B18: Azurill | C18: 190 | D18: Friendship | E18: 250 | F18: 3 | G18: Normal | H18: 1 | I18: 17
A19: =IFNA(VLOOKUP(B19,Sprites!$A$2:$B$1200,2,FALSE),"") | B19: Ralts | C19: 198 | D19: Level 20 | E19: 278 | F19: 4 | G19: Psychic | H19: 1 | I19: 18
A20: =IFNA(VLOOKUP(B20,Sprites!$A$2:$B$1200,2,FALSE),"")
A21: =IFNA(VLOOKUP(B21,Sprites!$A$2:$B$1200,2,FALSE),"") | B21: Date | C21: Change
A22: =IFNA(VLOOKUP(B22,Sprites!$A$2:$B$1200,2,FALSE),"") | B22: 46001 | C22: Flabebe moved from Rating 3 to 5. Morelull moved above Cottonee in Rating 3. Togepi weirdly still best fairy.
A23: =IFNA(VLOOKUP(B23,Sprites!$A$2:$B$1200,2,FALSE),"")
A24: =IFNA(VLOOKUP(B24,Sprites!$A$2:$B$1200,2,FALSE),"")
A25: =IFNA(VLOOKUP(B25,Sprites!$A$2:$B$1200,2,FALSE),"")
A26: =IFNA(VLOOKUP(B26,Sprites!$A$2:$B$1200,2,FALSE),"")
A27: =IFNA(VLOOKUP(B27,Sprites!$A$2:$B$1200,2,FALSE),"")
A28: =IFNA(VLOOKUP(B28,Sprites!$A$2:$B$1200,2,FALSE),"")
A29: =IFNA(VLOOKUP(B29,Sprites!$A$2:$B$1200,2,FALSE),"")
A30: =IFNA(VLOOKUP(B30,Sprites!$A$2:$B$1200,2,FALSE),"")
A31: =IFNA(VLOOKUP(B31,Sprites!$A$2:$B$1200,2,FALSE),"")
A32: =IFNA(VLOOKUP(B32,Sprites!$A$2:$B$1200,2,FALSE),"")
A33: =IFNA(VLOOKUP(B33,Sprites!$A$2:$B$1200,2,FALSE),"")
A34: =IFNA(VLOOKUP(B34,Sprites!$A$2:$B$1200,2,FALSE),"")
... A89: =IFNA(VLOOKUP(B89,Sprites!$A$2:$B$1200,2,FALSE),"")

Sheet Fighting
A1: ! | B1: Pokemon | C1: BST | D1: Evo method | E1: Target BST | F1: Moves 9 to Evo | G1: Alt Type | H1: Rating | I1: Ranking | J1: Number of mons | K1: 17
A2: =IFNA(VLOOKUP(B2,Sprites!$A$2:$B$1200,2,FALSE),"") | B2: Kubfu | C2: 385 | D2: Roguestone | E2: 550 | F2: 7 | H2: 9 | I2: 1 | J2: Average BST | K2: =SUM(C2:C1000)/K1 -> 320.58824
A3: =IFNA(VLOOKUP(B3,Sprites!$A$2:$B$1200,2,FALSE),"") | B3: Riolu | C3: 285 | D3: Friendship | E3: 525 | F3: 2 | H3: 8 | I3: 2 | J3: Average Rating | K3: =SUM(H2:H1000)/K1 -> 4.3529412
A4: =IFNA(VLOOKUP(B4,Sprites!$A$2:$B$1200,2,FALSE),"") | B4: Sneasel H | C4: 430 | D4: Roguestone | E4: 510 | F4: 6 | G4: Poison | H4: 7 | I4: 3 | J4: Roguestone # | K4: =COUNTIF(D2:D1000, "Roguestone") -> 3
A5: =IFNA(VLOOKUP(B5,Sprites!$A$2:$B$1200,2,FALSE),"") | B5: Farfetchd G | C5: 377 | D5: Level 34 | E5: 507 | F5: 5 | H5: 6 | I5: 4 | J5: Roguestone % | K5: =K4/K1 -> 0.17647059
A6: =IFNA(VLOOKUP(B6,Sprites!$A$2:$B$1200,2,FALSE),"") | B6: Mienfoo | C6: 350 | D6: Level 32 | E6: 510 | F6: 5 | H6: 6 | I6: 5
A7: =IFNA(VLOOKUP(B7,Sprites!$A$2:$B$1200,2,FALSE),"") | B7: Stufful | C7: 340 | D7: Level 27 | E7: 500 | F7: 4 | G7: Normal | H7: 6 | I7: 6
A8: =IFNA(VLOOKUP(B8,Sprites!$A$2:$B$1200,2,FALSE),"") | B8: Pancham | C8: 347 | D8: Level 32 | E8: 495 | F8: 5 | H8: 5 | I8: 7
A9: =IFNA(VLOOKUP(B9,Sprites!$A$2:$B$1200,2,FALSE),"") | B9: Timburr | C9: 305 | D9: Level 25 | E9: 405 | F9: 4 | H9: 4 | I9: 8
A10: =IFNA(VLOOKUP(B10,Sprites!$A$2:$B$1200,2,FALSE),"") | B10: Machop | C10: 305 | D10: Level 28 | E10: 405 | F10: 4 | H10: 4 | I10: 9
A11: =IFNA(VLOOKUP(B11,Sprites!$A$2:$B$1200,2,FALSE),"") | B11: Crabrawler | C11: 337 | D11: Roguestone | E11: 478 | F11: 7 | H11: 4 | I11: 10
A12: =IFNA(VLOOKUP(B12,Sprites!$A$2:$B$1200,2,FALSE),"") | B12: Scraggy | C12: 348 | D12: Level 39 | E12: 488 | F12: 7 | G12: Dark | H12: 3 | I12: 11
A13: =IFNA(VLOOKUP(B13,Sprites!$A$2:$B$1200,2,FALSE),"") | B13: Meditite | C13: 280 | D13: Level 37 | E13: 410 | F13: 11 | G13: Psychic | H13: 3 | I13: 12
A14: =IFNA(VLOOKUP(B14,Sprites!$A$2:$B$1200,2,FALSE),"") | B14: Clobbopus | C14: 309 | D14: Level 35 | E14: 480 | F14: 6 | H14: 2 | I14: 13
A15: =IFNA(VLOOKUP(B15,Sprites!$A$2:$B$1200,2,FALSE),"") | B15: Croagunk | C15: 300 | D15: Level 37 | E15: 490 | F15: 7 | G15: Poison | H15: 2 | I15: 14
A16: =IFNA(VLOOKUP(B16,Sprites!$A$2:$B$1200,2,FALSE),"") | B16: Mankey | C16: 305 | D16: Level 28 | E16: 455 | F16: 3 | H16: 2 | I16: 15
A17: =IFNA(VLOOKUP(B17,Sprites!$A$2:$B$1200,2,FALSE),"") | B17: Makuhita | C17: 237 | D17: Level 24 | E17: 474 | F17: 5 | H17: 2 | I17: 16
A18: =IFNA(VLOOKUP(B18,Sprites!$A$2:$B$1200,2,FALSE),"") | B18: Tyrogue | C18: 210 | D18: Level 20 | E18: 455 | F18: 0 | H18: 1 | I18: 17
B20: Date | C20: Change
B21: 46001 | C21: Sneasel moved down to Rating 7.

Sheet Fire
A1: ! | B1: Pokemon | C1: BST | D1: Evo method | E1: Target BST | F1: Moves 9 to Evo | G1: Alt Type | H1: Rating | I1: Ranking | J1: Number of mons | K1: 25
A2: =IFNA(VLOOKUP(B2,Sprites!$A$2:$B$1200,2,FALSE),"") | B2: Growlithe | C2: 350 | D2: Roguestone | E2: 555 | F2: 7 | H2: 9 | I2: 1 | J2: Average BST | K2: =SUM(C2:C1001)/K1 -> 318.64
A3: =IFNA(VLOOKUP(B3,Sprites!$A$2:$B$1200,2,FALSE),"") | B3: Larvesta | C3: 360 | D3: Level 40 | E3: 550 | F3: 5 | G3: Bug | H3: 8 | I3: 2 | J3: Average Rating | K3: =SUM(H2:H1001)/K1 -> 6.44
A4: =IFNA(VLOOKUP(B4,Sprites!$A$2:$B$1200,2,FALSE),"") | B4: Cyndaquil | C4: 309 | D4: Level 14 | E4: 405 | F4: 2 | H4: 8 | I4: 3 | J4: Roguestone # | K4: =COUNTIF(D2:D1000, "Roguestone") -> 5
A5: =IFNA(VLOOKUP(B5,Sprites!$A$2:$B$1200,2,FALSE),"") | B5: Torchic | C5: 310 | D5: Level 16 | E5: 405 | F5: 3 | H5: 8 | I5: 4 | J5: Roguestone % | K5: =K4/K1 -> 0.2
A6: =IFNA(VLOOKUP(B6,Sprites!$A$2:$B$1200,2,FALSE),"") | B6: Litten | C6: 320 | D6: Level 17 | E6: 420 | F6: 3 | H6: 8 | I6: 5
A7: =IFNA(VLOOKUP(B7,Sprites!$A$2:$B$1200,2,FALSE),"") | B7: Tepig | C7: 308 | D7: Level 17 | E7: 418 | F7: 3 | H7: 8 | I7: 6
A8: =IFNA(VLOOKUP(B8,Sprites!$A$2:$B$1200,2,FALSE),"") | B8: Chimchar | C8: 309 | D8: Level 14 | E8: 405 | F8: 1 | H8: 8 | I8: 7
A9: =IFNA(VLOOKUP(B9,Sprites!$A$2:$B$1200,2,FALSE),"") | B9: Fuecoco | C9: 310 | D9: Level 16 | E9: 411 | F9: 2 | H9: 8 | I9: 8
A10: =IFNA(VLOOKUP(B10,Sprites!$A$2:$B$1200,2,FALSE),"") | B10: Fennekin | C10: 307 | D10: Level 16 | E10: 409 | F10: 2 | H10: 8 | I10: 9
A11: =IFNA(VLOOKUP(B11,Sprites!$A$2:$B$1200,2,FALSE),"") | B11: Scorbunny | C11: 310 | D11: Level 16 | E11: 420 | F11: 1 | H11: 8 | I11: 10
A12: =IFNA(VLOOKUP(B12,Sprites!$A$2:$B$1200,2,FALSE),"") | B12: Charmander | C12: 309 | D12: Level 16 | E12: 405 | F12: 1 | H12: 8 | I12: 11
A13: =IFNA(VLOOKUP(B13,Sprites!$A$2:$B$1200,2,FALSE),"") | B13: Slugma | C13: 250 | D13: Level 18 | E13: 410 | F13: 1 | H13: 7 | I13: 12
A14: =IFNA(VLOOKUP(B14,Sprites!$A$2:$B$1200,2,FALSE),"") | B14: Houndour | C14: 330 | D14: Level 24 | E14: 495 | F14: 3 | G14: Dark | H14: 7 | I14: 13
A15: =IFNA(VLOOKUP(B15,Sprites!$A$2:$B$1200,2,FALSE),"") | B15: Litleo | C15: 369 | D15: Level 35 | E15: 507 | F15: 6 | G15: Normal | H15: 7 | I15: 14
A16: =IFNA(VLOOKUP(B16,Sprites!$A$2:$B$1200,2,FALSE),"") | B16: Growlithe H | C16: 350 | D16: Roguestone | E16: 555 | F16: 7 | G16: Rock | H16: 6 | I16: 15
A17: =IFNA(VLOOKUP(B17,Sprites!$A$2:$B$1200,2,FALSE),"") | B17: Ponyta | C17: 410 | D17: Level 40 | E17: 500 | F17: 6 | H17: 6 | I17: 16
A18: =IFNA(VLOOKUP(B18,Sprites!$A$2:$B$1200,2,FALSE),"") | B18: Charcadet | C18: 255 | D18: Roguestone | E18: 525 | F18: 6 | H18: 6 | I18: 17
A19: =IFNA(VLOOKUP(B19,Sprites!$A$2:$B$1200,2,FALSE),"") | B19: Magby | C19: 365 | D19: Level 30 | E19: 495 | F19: 5 | H19: 5 | I19: 18
A20: =IFNA(VLOOKUP(B20,Sprites!$A$2:$B$1200,2,FALSE),"") | B20: Sizzlipede | C20: 305 | D20: Level 28 | E20: 525 | F20: 4 | G20: Bug | H20: 5 | I20: 19
A21: =IFNA(VLOOKUP(B21,Sprites!$A$2:$B$1200,2,FALSE),"") | B21: Pansear | C21: 316 | D21: Roguestone | E21: 498 | F21: 9 | H21: 5 | I21: 20
A22: =IFNA(VLOOKUP(B22,Sprites!$A$2:$B$1200,2,FALSE),"") | B22: Vulpix | C22: 299 | D22: Roguestone | E22: 505 | F22: 6 | H22: 5 | I22: 21
A23: =IFNA(VLOOKUP(B23,Sprites!$A$2:$B$1200,2,FALSE),"") | B23: Darumaka | C23: 315 | D23: Level 35 | E23: 480 | F23: 6 | H23: 4 | I23: 22
A24: =IFNA(VLOOKUP(B24,Sprites!$A$2:$B$1200,2,FALSE),"") | B24: Salandit | C24: 320 | D24: Level 33 | E24: 480 | F24: 5 | G24: Poison | H24: 4 | I24: 23
A25: =IFNA(VLOOKUP(B25,Sprites!$A$2:$B$1200,2,FALSE),"") | B25: Litwick | C25: 275 | D25: Level 20 | E25: 370 | F25: 3 | G25: Ghost | H25: 3 | I25: 24
A26: =IFNA(VLOOKUP(B26,Sprites!$A$2:$B$1200,2,FALSE),"") | B26: Numel | C26: 305 | D26: Level 33 | E26: 460 | F26: 7 | G26: Ground | H26: 2 | I26: 25
A27: =IFNA(VLOOKUP(B27,Sprites!$A$2:$B$1200,2,FALSE),"")
A28: =IFNA(VLOOKUP(B28,Sprites!$A$2:$B$1200,2,FALSE),"")
A29: =IFNA(VLOOKUP(B29,Sprites!$A$2:$B$1200,2,FALSE),"")
A30: =IFNA(VLOOKUP(B30,Sprites!$A$2:$B$1200,2,FALSE),"")
A31: =IFNA(VLOOKUP(B31,Sprites!$A$2:$B$1200,2,FALSE),"")
A32: =IFNA(VLOOKUP(B32,Sprites!$A$2:$B$1200,2,FALSE),"")
A33: =IFNA(VLOOKUP(B33,Sprites!$A$2:$B$1200,2,FALSE),"")
A34: =IFNA(VLOOKUP(B34,Sprites!$A$2:$B$1200,2,FALSE),"")
A35: =IFNA(VLOOKUP(B35,Sprites!$A$2:$B$1200,2,FALSE),"")
A36: =IFNA(VLOOKUP(B36,Sprites!$A$2:$B$1200,2,FALSE),"")
A37: =IFNA(VLOOKUP(B37,Sprites!$A$2:$B$1200,2,FALSE),"")
A38: =IFNA(VLOOKUP(B38,Sprites!$A$2:$B$1200,2,FALSE),"")
... A89: =IFNA(VLOOKUP(B89,Sprites!$A$2:$B$1200,2,FALSE),"")

Sheet Flying
A1: ! | B1: Pokemon | C1: BST | D1: Evo method | E1: Target BST | F1: Moves 9 to Evo | G1: Alt Type | H1: Rating | I1: Ranking | J1: Number of mons | K1: 32
A2: =IFNA(VLOOKUP(B2,Sprites!$A$2:$B$1200,2,FALSE),"") | B2: Archen | C2: 401 | D2: Level 37 | E2: 567 | F2: 11 | G2: Rock | H2: 10 | I2: 1 | J2: Average BST | K2: =SUM(C2:C1001)/K1 -> 303.0625
A3: =IFNA(VLOOKUP(B3,Sprites!$A$2:$B$1200,2,FALSE),"") | B3: Gligar | C3: 430 | D3: Roguestone | E3: 510 | F3: 10 | G3: Ground | H3: 8 | I3: 2 | J3: Average Rating | K3: =SUM(H2:H1001)/K1 -> 4.21875
A4: =IFNA(VLOOKUP(B4,Sprites!$A$2:$B$1200,2,FALSE),"") | B4: Rowlet | C4: 320 | D4: Level 17 | E4: 420 | F4: 3 | G4: Grass | H4: 8 | I4: 3 | J4: Roguestone # | K4: =COUNTIF(D2:D1000, "Roguestone") -> 2
A5: =IFNA(VLOOKUP(B5,Sprites!$A$2:$B$1200,2,FALSE),"") | B5: Murkrow | C5: 405 | D5: Roguestone | E5: 505 | F5: 7 | G5: Dark | H5: 7 | I5: 4 | J5: Roguestone % | K5: =K4/K1 -> 0.0625
A6: =IFNA(VLOOKUP(B6,Sprites!$A$2:$B$1200,2,FALSE),"") | B6: Drifloon | C6: 348 | D6: Level 28 | E6: 498 | F6: 6 | G6: Ghost | H6: 6 | I6: 5
A7: =IFNA(VLOOKUP(B7,Sprites!$A$2:$B$1200,2,FALSE),"") | B7: Vullaby | C7: 370 | D7: Level 42 | E7: 510 | F7: 6 | G7: Dark | H7: 6 | I7: 6
A8: =IFNA(VLOOKUP(B8,Sprites!$A$2:$B$1200,2,FALSE),"") | B8: Yanma | C8: 313 | D8: Level 33 | E8: 515 | F8: 7 | G8: Bug | H8: 6 | I8: 7
A9: =IFNA(VLOOKUP(B9,Sprites!$A$2:$B$1200,2,FALSE),"") | B9: Mantyke | C9: 345 | D9: Level 35 | E9: 485 | F9: 6 | G9: Water | H9: 6 | I9: 8
A10: =IFNA(VLOOKUP(B10,Sprites!$A$2:$B$1200,2,FALSE),"") | B10: Starly | C10: 245 | D10: Level 14 | E10: 420 | F10: 2 | G10: Normal | H10: 5 | I10: 9
A11: =IFNA(VLOOKUP(B11,Sprites!$A$2:$B$1200,2,FALSE),"") | B11: Wattrel | C11: 280 | D11: Level 25 | E11: 490 | F11: 4 | G11: Electric | H11: 5 | I11: 10
A12: =IFNA(VLOOKUP(B12,Sprites!$A$2:$B$1200,2,FALSE),"") | B12: Rufflet | C12: 350 | D12: Level 40 | E12: 510 | F12: 5 | G12: Normal | H12: 5 | I12: 11
A13: =IFNA(VLOOKUP(B13,Sprites!$A$2:$B$1200,2,FALSE),"") | B13: Pikipek | C13: 265 | D13: Level 14 | E13: 384 | F13: 2 | G13: Normal | H13: 4 | I13: 12
A14: =IFNA(VLOOKUP(B14,Sprites!$A$2:$B$1200,2,FALSE),"") | B14: Fletchling | C14: 278 | D14: Level 17 | E14: 382 | F14: 2 | G14: Normal | H14: 4 | I14: 13
A15: =IFNA(VLOOKUP(B15,Sprites!$A$2:$B$1200,2,FALSE),"") | B15: Ledyba | C15: 265 | D15: Level 18 | E15: 390 | F15: 4 | G15: Bug | H15: 4 | I15: 14
A16: =IFNA(VLOOKUP(B16,Sprites!$A$2:$B$1200,2,FALSE),"") | B16: Natu | C16: 320 | D16: Level 25 | E16: 470 | F16: 3 | G16: Psychic | H16: 4 | I16: 15
A17: =IFNA(VLOOKUP(B17,Sprites!$A$2:$B$1200,2,FALSE),"") | B17: Doduo | C17: 310 | D17: Level 31 | E17: 470 | F17: 6 | G17: Normal | H17: 4 | I17: 16
A18: =IFNA(VLOOKUP(B18,Sprites!$A$2:$B$1200,2,FALSE),"") | B18: Woobat | C18: 323 | D18: Friendship | E18: 425 | F18: 5 | G18: Psychic | H18: 4 | I18: 17
A19: =IFNA(VLOOKUP(B19,Sprites!$A$2:$B$1200,2,FALSE),"") | B19: Rookidee | C19: 245 | D19: Level 18 | E19: 365 | F19: 2 | H19: 3 | I19: 18
A20: =IFNA(VLOOKUP(B20,Sprites!$A$2:$B$1200,2,FALSE),"") | B20: Hoppip | C20: 250 | D20: Level 18 | E20: 340 | F20: 5 | G20: Grass | H20: 3 | I20: 19
A21: =IFNA(VLOOKUP(B21,Sprites!$A$2:$B$1200,2,FALSE),"") | B21: Noibat | C21: 245 | D21: Level 32 | E21: 535 | F21: 6 | G21: Dragon | H21: 3 | I21: 20
A22: =IFNA(VLOOKUP(B22,Sprites!$A$2:$B$1200,2,FALSE),"") | B22: Farfetch'd | C22: 377 | D22: BST/10 | E22: 477 | F22: 8 | G22: Normal | H22: 3 | I22: 21
A23: =IFNA(VLOOKUP(B23,Sprites!$A$2:$B$1200,2,FALSE),"") | B23: Taillow | C23: 270 | D23: Level 22 | E23: 430 | F23: 4 | G23: Normal | H23: 3 | I23: 22
A24: =IFNA(VLOOKUP(B24,Sprites!$A$2:$B$1200,2,FALSE),"") | B24: Spearow | C24: 262 | D24: Level 20 | E24: 442 | F24: 3 | G24: Normal | H24: 3 | I24: 23
A25: =IFNA(VLOOKUP(B25,Sprites!$A$2:$B$1200,2,FALSE),"") | B25: Swablu | C25: 310 | D25: Level 35 | E25: 490 | F25: 6 | G25: Normal | H25: 3 | I25: 24
A26: =IFNA(VLOOKUP(B26,Sprites!$A$2:$B$1200,2,FALSE),"") | B26: Zubat | C26: 245 | D26: Level 22 | E26: 455 | F26: 3 | G26: Poison | H26: 3 | I26: 25
A27: =IFNA(VLOOKUP(B27,Sprites!$A$2:$B$1200,2,FALSE),"") | B27: Ducklett | C27: 305 | D27: Level 35 | E27: 473 | F27: 9 | G27: Water | H27: 3 | I27: 26
A28: =IFNA(VLOOKUP(B28,Sprites!$A$2:$B$1200,2,FALSE),"") | B28: Pidgey | C28: 251 | D28: Level 18 | E28: 349 | F28: 2 | G28: Normal | H28: 2 | I28: 27
A29: =IFNA(VLOOKUP(B29,Sprites!$A$2:$B$1200,2,FALSE),"") | B29: Wingull | C29: 270 | D29: Level 25 | E29: 440 | F29: 3 | G29: Water | H29: 2 | I29: 28
A30: =IFNA(VLOOKUP(B30,Sprites!$A$2:$B$1200,2,FALSE),"") | B30: Pidove | C30: 264 | D30: Level 21 | E30: 358 | F30: 3 | G30: Normal | H30: 2 | I30: 29
A31: =IFNA(VLOOKUP(B31,Sprites!$A$2:$B$1200,2,FALSE),"") | B31: Hoothoot | C31: 262 | D31: Level 20 | E31: 452 | F31: 4 | G31: Normal | H31: 2 | I31: 30
... A33: =IFNA(VLOOKUP(B33,Sprites!$A$2:$B$1200,2,FALSE),"") | B33: Delibird | C33: 330 | D33: BST/10 | E33: 430 | F33: 1 | G33: Ice | H33: 2 | I33: 32
A34: =IFNA(VLOOKUP(B34,Sprites!$A$2:$B$1200,2,FALSE),"")
A35: =IFNA(VLOOKUP(B35,Sprites!$A$2:$B$1200,2,FALSE),"")
A36: =IFNA(VLOOKUP(B36,Sprites!$A$2:$B$1200,2,FALSE),"")
A37: =IFNA(VLOOKUP(B37,Sprites!$A$2:$B$1200,2,FALSE),"")
A38: =IFNA(VLOOKUP(B38,Sprites!$A$2:$B$1200,2,FALSE),"")
A39: =IFNA(VLOOKUP(B39,Sprites!$A$2:$B$1200,2,FALSE),"")
A40: =IFNA(VLOOKUP(B40,Sprites!$A$2:$B$1200,2,FALSE),"")
A41: =IFNA(VLOOKUP(B41,Sprites!$A$2:$B$1200,2,FALSE),"")
...

Sheet Ghost
A1: ! | B1: Pokemon | C1: BST | D1: Evo method | E1: Target BST | F1: Moves 9 to Evo | G1: Alt Type | H1: Rating | I1: Ranking | J1: Number of mons | K1: 23
A2: =IFNA(VLOOKUP(B2,Sprites!$A$2:$B$1200,2,FALSE),"") | B2: Corsola G | C2: 410 | D2: Level 38 | E2: 510 | F2: 6 | H2: 9 | I2: 1 | J2: Average BST | K2: =SUM(C2:C1000)/K1 -> 320.08696
A3: =IFNA(VLOOKUP(B3,Sprites!$A$2:$B$1200,2,FALSE),"") | B3: Zorua H | C3: 330 | D3: Level 30 | E3: 510 | F3: 5 | G3: Normal | H3: 8 | I3: 2 | J3: Average Rating | K3: =SUM(H2:H1000)/K1 -> 4.4347826
A4: =IFNA(VLOOKUP(B4,Sprites!$A$2:$B$1200,2,FALSE),"") | B4: Misdreavus | C4: 435 | D4: Roguestone | E4: 495 | F4: 10 | H4: 7 | I4: 3 | J4: Roguestone # | K4: =COUNTIF(D2:D1000, "Roguestone") -> 5
A5: =IFNA(VLOOKUP(B5,Sprites!$A$2:$B$1200,2,FALSE),"") | B5: Bramblin | C5: 275 | D5: Friendship | E5: 480 | F5: 2 | G5: Grass | H5: 6 | I5: 4 | J5: Roguestone % | K5: =K4/K1 -> 0.2173913
A6: =IFNA(VLOOKUP(B6,Sprites!$A$2:$B$1200,2,FALSE),"") | B6: Sableye | C6: 380 | D6: BST/10 | E6: 480 | F6: 14 | G6: Dark | H6: 6 | I6: 5
A7: =IFNA(VLOOKUP(B7,Sprites!$A$2:$B$1200,2,FALSE),"") | B7: Drifloon | C7: 348 | D7: Level 28 | E7: 498 | F7: 6 | G7: Flying | H7: 6 | I7: 6
A8: =IFNA(VLOOKUP(B8,Sprites!$A$2:$B$1200,2,FALSE),"") | B8: Gimmighoul | C8: 300 | D8: Level 34 | E8: 550 | F8: 0 | H8: 5 | I8: 7
A9: =IFNA(VLOOKUP(B9,Sprites!$A$2:$B$1200,2,FALSE),"") | B9: Gastly | C9: 310 | D9: Level 25 | E9: 405 | F9: 4 | G9: Poison | H9: 5 | I9: 8
A10: =IFNA(VLOOKUP(B10,Sprites!$A$2:$B$1200,2,FALSE),"") | B10: Honedge | C10: 325 | D10: Level 35 | E10: 448 | F10: 6 | G10: Steel | H10: 5 | I10: 9
A11: =IFNA(VLOOKUP(B11,Sprites!$A$2:$B$1200,2,FALSE),"") | B11: Dreepy | C11: 270 | D11: Level 30 | E11: 410 | F11: 0 | G11: Dragon | H11: 4 | I11: 10
A12: =IFNA(VLOOKUP(B12,Sprites!$A$2:$B$1200,2,FALSE),"") | B12: Pumpkaboo | C12: 335 | D12: Roguestone | E12: 494 | F12: 9 | G12: Grass | H12: 4 | I12: 11
A13: =IFNA(VLOOKUP(B13,Sprites!$A$2:$B$1200,2,FALSE),"") | B13: Frillish | C13: 335 | D13: Level 40 | E13: 480 | F13: 7 | G13: Water | H13: 4 | I13: 12
A14: =IFNA(VLOOKUP(B14,Sprites!$A$2:$B$1200,2,FALSE),"") | B14: Sinistea | C14: 308 | D14: Roguestone | E14: 508 | F14: 4 | H14: 4 | I14: 13
A15: =IFNA(VLOOKUP(B15,Sprites!$A$2:$B$1200,2,FALSE),"") | B15: Polchgeist | C15: 308 | D15: Roguestone | E15: 508 | F15: 5 | G15: Grass | H15: 4 | I15: 14
A16: =IFNA(VLOOKUP(B16,Sprites!$A$2:$B$1200,2,FALSE),"") | B16: Yamask | C16: 303 | D16: Level 34 | E16: 483 | F16: 6 | H16: 4 | I16: 15
A17: =IFNA(VLOOKUP(B17,Sprites!$A$2:$B$1200,2,FALSE),"") | B17: Yamask G | C17: 303 | D17: Level 34 | E17: 483 | F17: 6 | G17: Ground | H17: 4 | I17: 16
A18: =IFNA(VLOOKUP(B18,Sprites!$A$2:$B$1200,2,FALSE),"") | B18: Litwick | C18: 275 | D18: Level 20 | E18: 370 | F18: 3 | G18: Fire | H18: 3 | I18: 17
A19: =IFNA(VLOOKUP(B19,Sprites!$A$2:$B$1200,2,FALSE),"") | B19: Greavard | C19: 290 | D19: Level 30 | E19: 470 | F19: 5 | H19: 3 | I19: 18
A20: =IFNA(VLOOKUP(B20,Sprites!$A$2:$B$1200,2,FALSE),"") | B20: Phantump | C20: 309 | D20: Roguestone | E20: 474 | F20: 7 | G20: Grass | H20: 3 | I20: 19
A21: =IFNA(VLOOKUP(B21,Sprites!$A$2:$B$1200,2,FALSE),"") | B21: Sandygast | C21: 320 | D21: Level 42 | E21: 485 | F21: 7 | G21: Ground | H21: 2 | I21: 20
A22: =IFNA(VLOOKUP(B22,Sprites!$A$2:$B$1200,2,FALSE),"") | B22: Golett | C22: 303 | D22: Level 43 | E22: 483 | F22: 8 | G22: Ground | H22: 2 | I22: 21
A23: =IFNA(VLOOKUP(B23,Sprites!$A$2:$B$1200,2,FALSE),"") | B23: Duskull | C23: 295 | D23: Level 37 | E23: 455 | F23: 7 | H23: 2 | I23: 22
A24: =IFNA(VLOOKUP(B24,Sprites!$A$2:$B$1200,2,FALSE),"") | B24: Shuppet | C24: 295 | D24: Level 37 | E24: 455 | F24: 7 | H24: 2 | I24: 23
A25: =IFNA(VLOOKUP(B25,Sprites!$A$2:$B$1200,2,FALSE),"")
A26: =IFNA(VLOOKUP(B26,Sprites!$A$2:$B$1200,2,FALSE),"")
A27: =IFNA(VLOOKUP(B27,Sprites!$A$2:$B$1200,2,FALSE),"")
A28: =IFNA(VLOOKUP(B28,Sprites!$A$2:$B$1200,2,FALSE),"")
A29: =IFNA(VLOOKUP(B29,Sprites!$A$2:$B$1200,2,FALSE),"")
A30: =IFNA(VLOOKUP(B30,Sprites!$A$2:$B$1200,2,FALSE),"")
A31: =IFNA(VLOOKUP(B31,Sprites!$A$2:$B$1200,2,FALSE),"")
A32: =IFNA(VLOOKUP(B32,Sprites!$A$2:$B$1200,2,FALSE),"")
A33: =IFNA(VLOOKUP(B33,Sprites!$A$2:$B$1200,2,FALSE),"")
A34: =IFNA(VLOOKUP(B34,Sprites!$A$2:$B$1200,2,FALSE),"")
A35: =IFNA(VLOOKUP(B35,Sprites!$A$2:$B$1200,2,FALSE),"")
A36: =IFNA(VLOOKUP(B36,Sprites!$A$2:$B$1200,2,FALSE),"")
... A88: =IFNA(VLOOKUP(B88,Sprites!$A$2:$B$1200,2,FALSE),"")

Sheet Grass
A1: ! | B1: Pokemon | C1: BST | D1: Evo method | E1: Target BST | F1: Moves 9 to Evo | G1: Alt Type | H1: Rating | I1: Ranking | J1: Number of mons | K1: 45
A2: =IFNA(VLOOKUP(B2,Sprites!$A$2:$B$1200,2,FALSE),"") | B2: Tangela | C2: 435 | D2: Level 38 | E2: 535 | F2: 7 | H2: 9 | I2: 1 | J2: Average BST | K2: =SUM(C2:C1001)/K1 -> 298.13333
A3: =IFNA(VLOOKUP(B3,Sprites!$A$2:$B$1200,2,FALSE),"") | B3: Skiddo | C3: 350 | D3: Level 32 | E3: 531 | F3: 8 | H3: 8 | I3: 2 | J3: Average Rating | K3: =SUM(H2:H1001)/K1 -> 4.5333333
A4: =IFNA(VLOOKUP(B4,Sprites!$A$2:$B$1200,2,FALSE),"") | B4: Bulbasaur | C4: 318 | D4: Level 16 | E4: 405 | F4: 4 | G4: Poison | H4: 8 | I4: 3 | J4: Roguestone # | K4: =COUNTIF(D2:D1000, "Roguestone") -> 10
A5: =IFNA(VLOOKUP(B5,Sprites!$A$2:$B$1200,2,FALSE),"") | B5: Rowlet | C5: 320 | D5: Level 17 | E5: 420 | F5: 3 | G5: Flying | H5: 8 | I5: 4 | J5: Roguestone % | K5: =K4/K1 -> 0.22222222
A6: =IFNA(VLOOKUP(B6,Sprites!$A$2:$B$1200,2,FALSE),"") | B6: Sprigatito | C6: 310 | D6: Level 16 | E6: 410 | F6: 3 | H6: 8 | I6: 5
A7: =IFNA(VLOOKUP(B7,Sprites!$A$2:$B$1200,2,FALSE),"") | B7: Treecko | C7: 310 | D7: Level 16 | E7: 405 | F7: 3 | H7: 8 | I7: 6
A8: =IFNA(VLOOKUP(B8,Sprites!$A$2:$B$1200,2,FALSE),"") | B8: Snivy | C8: 308 | D8: Level 17 | E8: 413 | F8: 3 | H8: 8 | I8: 7
A9: =IFNA(VLOOKUP(B9,Sprites!$A$2:$B$1200,2,FALSE),"") | B9: Turtwig | C9: 320 | D9: Level 18 | E9: 405 | F9: 3 | H9: 8 | I9: 8
A10: =IFNA(VLOOKUP(B10,Sprites!$A$2:$B$1200,2,FALSE),"") | B10: Chikorita | C10: 318 | D10: Level 16 | E10: 405 | F10: 2 | H10: 8 | I10: 9
A11: =IFNA(VLOOKUP(B11,Sprites!$A$2:$B$1200,2,FALSE),"") | B11: Chespin | C11: 313 | D11: Level 16 | E11: 405 | F11: 2 | H11: 8 | I11: 10
A12: =IFNA(VLOOKUP(B12,Sprites!$A$2:$B$1200,2,FALSE),"") | B12: Grookey | C12: 310 | D12: Level 16 | E12: 420 | F12: 1 | H12: 8 | I12: 11
A13: =IFNA(VLOOKUP(B13,Sprites!$A$2:$B$1200,2,FALSE),"") | B13: Exeggcute | C13: 325 | D13: Roguestone | E13: 530 | F13: 6 | G13: Psychic | H13: 7 | I13: 12
A14: =IFNA(VLOOKUP(B14,Sprites!$A$2:$B$1200,2,FALSE),"") | B14: Bramblin | C14: 275 | D14: Friendship | E14: 480 | F14: 2 | G14: Ghost | H14: 6 | I14: 13
A15: =IFNA(VLOOKUP(B15,Sprites!$A$2:$B$1200,2,FALSE),"") | B15: Deerling | C15: 350 | D15: Level 34 | E15: 490 | F15: 7 | G15: Normal | H15: 6 | I15: 14
A16: =IFNA(VLOOKUP(B16,Sprites!$A$2:$B$1200,2,FALSE),"") | B16: Oddish | C16: 320 | D16: Level 21 | E16: 395 | F16: 5 | G16: Poison | H16: 6 | I16: 15
A17: =IFNA(VLOOKUP(B17,Sprites!$A$2:$B$1200,2,FALSE),"") | B17: Bellsprout | C17: 300 | D17: Level 21 | E17: 390 | F17: 4 | G17: Poison | H17: 6 | I17: 16
A18: =IFNA(VLOOKUP(B18,Sprites!$A$2:$B$1200,2,FALSE),"") | B18: Budew | C18: 280 | D18: Friendship | E18: 420 | F18: 0 | G18: Poison | H18: 5 | I18: 17
A19: =IFNA(VLOOKUP(B19,Sprites!$A$2:$B$1200,2,FALSE),"") | B19: Pansage | C19: 316 | D19: Roguestone | E19: 498 | F19: 9 | H19: 5 | I19: 18
A20: =IFNA(VLOOKUP(B20,Sprites!$A$2:$B$1200,2,FALSE),"") | B20: Lileep | C20: 355 | D20: Level 40 | E20: 495 | F20: 7 | G20: Rock | H20: 5 | I20: 19
A21: =IFNA(VLOOKUP(B21,Sprites!$A$2:$B$1200,2,FALSE),"") | B21: Snover | C21: 334 | D21: Level 28 | E21: 494 | F21: 4 | G21: Ice | H21: 4 | I21: 20
A22: =IFNA(VLOOKUP(B22,Sprites!$A$2:$B$1200,2,FALSE),"") | B22: Pumpkaboo | C22: 335 | D22: Roguestone | E22: 494 | F22: 9 | G22: Ghost | H22: 4 | I22: 21
A23: =IFNA(VLOOKUP(B23,Sprites!$A$2:$B$1200,2,FALSE),"") | B23: Voltorb H | C23: 330 | D23: Roguestone | E23: 485 | F23: 10 | G23: Electric | H23: 4 | I23: 22
A24: =IFNA(VLOOKUP(B24,Sprites!$A$2:$B$1200,2,FALSE),"") | B24: Cacnea | C24: 335 | D24: Level 32 | E24: 475 | F24: 7 | H24: 4 | I24: 23
A25: =IFNA(VLOOKUP(B25,Sprites!$A$2:$B$1200,2,FALSE),"") | B25: Capsakid | C25: 304 | D25: Roguestone | E25: 486 | F25: 6 | H25: 4 | I25: 24
A26: =IFNA(VLOOKUP(B26,Sprites!$A$2:$B$1200,2,FALSE),"") | B26: Toedscool | C26: 335 | D26: Level 30 | E26: 485 | F26: 6 | G26: Ground | H26: 3 | I26: 25
A27: =IFNA(VLOOKUP(B27,Sprites!$A$2:$B$1200,2,FALSE),"") | B27: Hoppip | C27: 250 | D27: Level 18 | E27: 340 | F27: 5 | G27: Flying | H27: 3 | I27: 26
A28: =IFNA(VLOOKUP(B28,Sprites!$A$2:$B$1200,2,FALSE),"") | B28: Polchgeist | C28: 308 | D28: Roguestone | E28: 508 | F28: 5 | G28: Ghost | H28: 3 | I28: 27
A29: =IFNA(VLOOKUP(B29,Sprites!$A$2:$B$1200,2,FALSE),"") | B29: Morelull | C29: 285 | D29: Level 24 | E29: 405 | F29: 3 | G29: Fairy | H29: 3 | I29: 28
A30: =IFNA(VLOOKUP(B30,Sprites!$A$2:$B$1200,2,FALSE),"") | B30: Phantump | C30: 309 | D30: Roguestone | E30: 474 | F30: 7 | G30: Ghost | H30: 3 | I30: 29
A31: =IFNA(VLOOKUP(B31,Sprites!$A$2:$B$1200,2,FALSE),"") | B31: Petilil | C31: 280 | D31: Roguestone | E31: 480 | F31: 8 | H31: 3 | I31: 30
A32: =IFNA(VLOOKUP(B32,Sprites!$A$2:$B$1200,2,FALSE),"") | B32: Cottonee | C32: 280 | D32: Roguestone | E32: 480 | F32: 9 | G32: Fairy | H32: 3 | I32: 31
A33: =IFNA(VLOOKUP(B33,Sprites!$A$2:$B$1200,2,FALSE),"") | B33: Sewaddle | C33: 310 | D33: Level 20 | E33: 380 | F33: 1 | G33: Bug | H33: 2 | I33: 32
A34: =IFNA(VLOOKUP(B34,Sprites!$A$2:$B$1200,2,FALSE),"") | B34: Ferroseed | C34: 305 | D34: Level 40 | E34: 489 | F34: 5 | G34: Steel | H34: 2 | I34: 33
A35: =IFNA(VLOOKUP(B35,Sprites!$A$2:$B$1200,2,FALSE),"") | B35: Bounsweet | C35: 210 | D35: Level 18 | E35: 350 | F35: 2 | H35: 2 | I35: 34
A36: =IFNA(VLOOKUP(B36,Sprites!$A$2:$B$1200,2,FALSE),"") | B36: Applin | C36: 260 | D36: Roguestone | E36: 485 | F36: 0 | G36: Dragon | H36: 2 | I36: 35
A37: =IFNA(VLOOKUP(B37,Sprites!$A$2:$B$1200,2,FALSE),"") | B37: Fomantis | C37: 250 | D37: Level 34 | E37: 480 | F37: 5 | H37: 2 | I37: 36
A38: =IFNA(VLOOKUP(B38,Sprites!$A$2:$B$1200,2,FALSE),"") | B38: Lotad | C38: 220 | D38: Level 14 | E38: 340 | F38: 2 | G38: Water | H38: 2 | I38: 37
A39: =IFNA(VLOOKUP(B39,Sprites!$A$2:$B$1200,2,FALSE),"") | B39: Seedot | C39: 220 | D39: Level 14 | E39: 380 | F39: 2 | H39: 2 | I39: 38
A40: =IFNA(VLOOKUP(B40,Sprites!$A$2:$B$1200,2,FALSE),"") | B40: Sunkern | C40: 180 | D40: Level 18 | E40: 425 | F40: 2 | H40: 2 | I40: 39
...

Sheet Ground
A1: ! | B1: Pokemon | C1: BST | D1: Evo method | E1: Target BST | F1: Moves 9 to Evo | G1: Alt Type | H1: Rating | I1: Ranking | J1: Number of mons | K1: 28
A2: =IFNA(VLOOKUP(B2,Sprites!$A$2:$B$1200,2,FALSE),"") | B2: Gligar | C2: 430 | D2: Roguestone | E2: 510 | F2: 10 | G2: Flying | H2: 8 | I2: 1 | J2: Average BST | K2: =SUM(C2:C1000)/K1 -> 305
A3: =IFNA(VLOOKUP(B3,Sprites!$A$2:$B$1200,2,FALSE),"") | B3: Gible | C3: 300 | D3: Level 24 | E3: 410 | F3: 2 | G3: Dragon | H3: 7 | I3: 2 | J3: Average Rating | K3: =SUM(H2:H1000)/K1 -> 3.5357143
A4: =IFNA(VLOOKUP(B4,Sprites!$A$2:$B$1200,2,FALSE),"") | B4: Mudbray | C4: 385 | D4: Level 30 | E4: 500 | F4: 5 | H4: 7 | I4: 3 | J4: Roguestone # | K4: =COUNTIF(D2:D1000, "Roguestone") -> 2
A5: =IFNA(VLOOKUP(B5,Sprites!$A$2:$B$1200,2,FALSE),"") | B5: Hippopotas | C5: 300 | D5: Level 34 | E5: 525 | F5: 6 | H5: 6 | I5: 4 | J5: Roguestone % | K5: =K4/K1 -> 0.071428571
A6: =IFNA(VLOOKUP(B6,Sprites!$A$2:$B$1200,2,FALSE),"") | B6: Silicobra | C6: 315 | D6: Level 36 | E6: 510 | F6: 6 | H6: 6 | I6: 5
A7: =IFNA(VLOOKUP(B7,Sprites!$A$2:$B$1200,2,FALSE),"") | B7: Phanpy | C7: 330 | D7: Level 25 | E7: 500 | F7: 4 | H7: 5 | I7: 6
A8: =IFNA(VLOOKUP(B8,Sprites!$A$2:$B$1200,2,FALSE),"") | B8: Drilbur | C8: 328 | D8: Level 31 | E8: 508 | F8: 5 | H8: 5 | I8: 7
A9: =IFNA(VLOOKUP(B9,Sprites!$A$2:$B$1200,2,FALSE),"") | B9: Cubone | C9: 320 | D9: Level 28 | E9: 425 | F9: 4 | H9: 5 | I9: 8
A10: =IFNA(VLOOKUP(B10,Sprites!$A$2:$B$1200,2,FALSE),"") | B10: Baltoy | C10: 300 | D10: Level 36 | E10: 500 | F10: 11 | G10: Psychic | H10: 5 | I10: 9
A11: =IFNA(VLOOKUP(B11,Sprites!$A$2:$B$1200,2,FALSE),"") | B11: Yamask G | C11: 303 | D11: Level 34 | E11: 483 | F11: 6 | G11: Ghost | H11: 4 | I11: 10
A12: =IFNA(VLOOKUP(B12,Sprites!$A$2:$B$1200,2,FALSE),"") | B12: Diglett | C12: 265 | D12: Level 26 | E12: 405 | F12: 4 | H12: 4 | I12: 11
A13: =IFNA(VLOOKUP(B13,Sprites!$A$2:$B$1200,2,FALSE),"") | B13: Onix | C13: 385 | D13: Roguestone | E13: 510 | F13: 10 | G13: Rock | H13: 3 | I13: 12
A14: =IFNA(VLOOKUP(B14,Sprites!$A$2:$B$1200,2,FALSE),"") | B14: Diglett A | C14: 265 | D14: Level 26 | E14: 405 | F14: 4 | G14: Steel | H14: 3 | I14: 13
A15: =IFNA(VLOOKUP(B15,Sprites!$A$2:$B$1200,2,FALSE),"") | B15: Toedscool | C15: 335 | D15: Level 30 | E15: 485 | F15: 6 | G15: Grass | H15: 3 | I15: 14
A16: =IFNA(VLOOKUP(B16,Sprites!$A$2:$B$1200,2,FALSE),"") | B16: Larvitar | C16: 300 | D16: Level 30 | E16: 410 | F16: 7 | G16: Rock | H16: 3 | I16: 15
A17: =IFNA(VLOOKUP(B17,Sprites!$A$2:$B$1200,2,FALSE),"") | B17: Sandile | C17: 292 | D17: Level 29 | E17: 351 | F17: 7 | G17: Dark | H17: 3 | I17: 16
A18: =IFNA(VLOOKUP(B18,Sprites!$A$2:$B$1200,2,FALSE),"") | B18: Rhyhorn | C18: 345 | D18: Level 28 | E18: 485 | F18: 4 | G18: Rock | H18: 2 | I18: 17
A19: =IFNA(VLOOKUP(B19,Sprites!$A$2:$B$1200,2,FALSE),"") | B19: Geodude | C19: 300 | D19: Level 25 | E19: 390 | F19: 5 | G19: Rock | H19: 2 | I19: 18
A20: =IFNA(VLOOKUP(B20,Sprites!$A$2:$B$1200,2,FALSE),"") | B20: Nincada | C20: 266 | D20: Level 20 | E20: 456/256 | F20: 2 | G20: Bug | H20: 2 | I20: 19
A21: =IFNA(VLOOKUP(B21,Sprites!$A$2:$B$1200,2,FALSE),"") | B21: Sandygast | C21: 320 | D21: Level 42 | E21: 485 | F21: 7 | G21: Ghost | H21: 2 | I21: 20
A22: =IFNA(VLOOKUP(B22,Sprites!$A$2:$B$1200,2,FALSE),"") | B22: Golett | C22: 303 | D22: Level 43 | E22: 483 | F22: 8 | G22: Ghost | H22: 2 | I22: 21
A23: =IFNA(VLOOKUP(B23,Sprites!$A$2:$B$1200,2,FALSE),"") | B23: Swinub | C23: 250 | D23: Level 33 | E23: 430 | F23: 5 | G23: Ice | H23: 2 | I23: 22
A24: =IFNA(VLOOKUP(B24,Sprites!$A$2:$B$1200,2,FALSE),"") | B24: Trapinch | C24: 290 | D24: Level 35 | E24: 340 | F24: 6 | H24: 2 | I24: 23
A25: =IFNA(VLOOKUP(B25,Sprites!$A$2:$B$1200,2,FALSE),"") | B25: Sandshrew | C25: 300 | D25: Level 22 | E25: 450 | F25: 5 | H25: 2 | I25: 24
A26: =IFNA(VLOOKUP(B26,Sprites!$A$2:$B$1200,2,FALSE),"") | B26: Numel | C26: 305 | D26: Level 33 | E26: 460 | F26: 7 | G26: Fire | H26: 2 | I26: 25
A27: =IFNA(VLOOKUP(B27,Sprites!$A$2:$B$1200,2,FALSE),"") | B27: Barboach | C27: 288 | D27: Level 30 | E27: 468 | F27: 3 | G27: Water | H27: 2 | I27: 26
A28: =IFNA(VLOOKUP(B28,Sprites!$A$2:$B$1200,2,FALSE),"") | B28: Wooper | C28: 210 | D28: Level 20 | E28: 430 | F28: 3 | G28: Water | H28: 1 | I28: 27
A29: =IFNA(VLOOKUP(B29,Sprites!$A$2:$B$1200,2,FALSE),"") | B29: Wooper P | C29: 210 | D29: Level 20 | E29: 430 | F29: 2 | G29: Poison | H29: 1 | I29: 28
A30: =IFNA(VLOOKUP(B30,Sprites!$A$2:$B$1200,2,FALSE),"")
A31: =IFNA(VLOOKUP(B31,Sprites!$A$2:$B$1200,2,FALSE),"")
A32: =IFNA(VLOOKUP(B32,Sprites!$A$2:$B$1200,2,FALSE),"")
A33: =IFNA(VLOOKUP(B33,Sprites!$A$2:$B$1200,2,FALSE),"")
A34: =IFNA(VLOOKUP(B34,Sprites!$A$2:$B$1200,2,FALSE),"")
A35: =IFNA(VLOOKUP(B35,Sprites!$A$2:$B$1200,2,FALSE),"")
A36: =IFNA(VLOOKUP(B36,Sprites!$A$2:$B$1200,2,FALSE),"")
A37: =IFNA(VLOOKUP(B37,Sprites!$A$2:$B$1200,2,FALSE),"")
A38: =IFNA(VLOOKUP(B38,Sprites!$A$2:$B$1200,2,FALSE),"")
A39: =IFNA(VLOOKUP(B39,Sprites!$A$2:$B$1200,2,FALSE),"")
A40: =IFNA(VLOOKUP(B40,Sprites!$A$2:$B$1200,2,FALSE),"")
...

Sheet Ice
A1: ! | B1: Pokemon | C1: BST | D1: Evo method | E1: Target BST | F1: Moves 9 to Evo | G1: Alt Type | H1: Rating | I1: Ranking | J1: Number of mons | K1: 17
A2: =IFNA(VLOOKUP(B2,Sprites!$A$2:$B$1200,2,FALSE),"") | B2: Sneasel | C2: 430 | D2: Roguestone | E2: 510 | F2: 7 | G2: Dark | H2: 7 | I2: 1 | J2: Average BST | K2: =SUM(C2:C1000)/K1 -> 309.88235
A3: =IFNA(VLOOKUP(B3,Sprites!$A$2:$B$1200,2,FALSE),"") | B3: Amaura | C3: 362 | D3: Level 30 | E3: 521 | F3: 5 | G3: Rock | H3: 7 | I3: 2 | J3: Average Rating | K3: =SUM(H2:H1000)/K1 -> 4.0588235
A4: =IFNA(VLOOKUP(B4,Sprites!$A$2:$B$1200,2,FALSE),"") | B4: Cetoddle | C4: 334 | D4: Roguestone | E4: 521 | F4: 8 | H4: 7 | I4: 3 | J4: Roguestone # | K4: =COUNTIF(D2:D1000, "Roguestone") -> 5
A5: =IFNA(VLOOKUP(B5,Sprites!$A$2:$B$1200,2,FALSE),"") | B5: Bergmite | C5: 304 | D5: Level 37 | E5: 514 | F5: 11 | H5: 6 | I5: 4 | J5: Roguestone % | K5: =K4/K1 -> 0.29411765
A6: =IFNA(VLOOKUP(B6,Sprites!$A$2:$B$1200,2,FALSE),"") | B6: Cubchoo | C6: 305 | D6: Level 37 | E6: 505 | F6: 11 | H6: 6 | I6: 5
A7: =IFNA(VLOOKUP(B7,Sprites!$A$2:$B$1200,2,FALSE),"") | B7: Frigibax | C7: 320 | D7: Level 35 | E7: 423 | F7: 5 | G7: Dragon | H7: 5 | I7: 6
A8: =IFNA(VLOOKUP(B8,Sprites!$A$2:$B$1200,2,FALSE),"") | B8: Vanillite | C8: 305 | D8: Level 35 | E8: 395 | F8: 6 | H8: 5 | I8: 7
A9: =IFNA(VLOOKUP(B9,Sprites!$A$2:$B$1200,2,FALSE),"") | B9: Vulpix A | C9: 299 | D9: Roguestone | E9: 505 | F9: 8 | H9: 4 | I9: 8
A10: =IFNA(VLOOKUP(B10,Sprites!$A$2:$B$1200,2,FALSE),"") | B10: Snover | C10: 334 | D10: Level 28 | E10: 494 | F10: 4 | G10: Grass | H10: 4 | I10: 9
A11: =IFNA(VLOOKUP(B11,Sprites!$A$2:$B$1200,2,FALSE),"") | B11: Spheal | C11: 290 | D11: Level 32 | E11: 410 | F11: 5 | G11: Water | H11: 3 | I11: 10
A12: =IFNA(VLOOKUP(B12,Sprites!$A$2:$B$1200,2,FALSE),"") | B12: Darumaka G | C12: 315 | D12: Roguestone | E12: 480 | F12: 7 | H12: 3 | I12: 11
A13: =IFNA(VLOOKUP(B13,Sprites!$A$2:$B$1200,2,FALSE),"") | B13: Snorunt | C13: 300 | D13: Roguestone/42 | E13: 480 | F13: 7 | H13: 3 | I13: 12
A14: =IFNA(VLOOKUP(B14,Sprites!$A$2:$B$1200,2,FALSE),"") | B14: Sandshrew A | C14: 300 | D14: Roguestone | E14: 450 | F14: 11 | G14: Steel | H14: 2 | I14: 13
A15: =IFNA(VLOOKUP(B15,Sprites!$A$2:$B$1200,2,FALSE),"") | B15: Smoochum | C15: 305 | D15: Level 30 | E15: 455 | F15: 5 | G15: Psychic | H15: 2 | I15: 14
A16: =IFNA(VLOOKUP(B16,Sprites!$A$2:$B$1200,2,FALSE),"") | B16: Delibird | C16: 330 | D16: BST/10 | E16: 430 | F16: 1 | G16: Flying | H16: 2 | I16: 15
A17: =IFNA(VLOOKUP(B17,Sprites!$A$2:$B$1200,2,FALSE),"") | B17: Swinub | C17: 250 | D17: Level 33 | E17: 450 | F17: 5 | G17: Ground | H17: 2 | I17: 16
A18: =IFNA(VLOOKUP(B18,Sprites!$A$2:$B$1200,2,FALSE),"") | B18: Snom | C18: 185 | D18: Friendship | E18: 475 | F18: 0 | G18: Bug | H18: 1 | I18: 17
B20: Date | C20: Change
B21: 46001 | C21: Sneasel moved down to rating 7.

Sheet Normal
A1: ! | B1: Pokemon | C1: BST | D1: Evo method | E1: Target BST | F1: Moves 9 to Evo | G1: Alt Type | H1: Rating | I1: Ranking | J1: Number of mons | K1: 55
A2: =IFNA(VLOOKUP(B2,Sprites!$A$2:$B$1200,2,FALSE),"") | B2: Stantler | C2: 465 | D2: Level 41 | E2: 525 | F2: 8 | H2: 10 | I2: 1 | J2: Average BST | K2: =SUM(C2:C1001)/K1 -> 296.36364
A3: =IFNA(VLOOKUP(B3,Sprites!$A$2:$B$1200,2,FALSE),"") | B3: Girafarig | C3: 455 | D3: Level 32 | E3: 520 | F3: 6 | G3: Psychic | H3: 9 | I3: 2 | J3: Average Rating | K3: =SUM(H2:H1001)/K1 -> 4.1818182
A4: =IFNA(VLOOKUP(B4,Sprites!$A$2:$B$1200,2,FALSE),"") | B4: Munchlax | C4: 390 | D4: Friendship | E4: 540 | F4: 11 | H4: 8 | I4: 3 | J4: Roguestone # | K4: =COUNTIF(D2:D1000, "Roguestone") -> 5
A5: =IFNA(VLOOKUP(B5,Sprites!$A$2:$B$1200,2,FALSE),"") | B5: Dunsparce | C5: 415 | D5: Level 32 | E5: 520 | F5: 6 | H5: 8 | I5: 4 | J5: Roguestone % | K5: =K4/K1 -> 0.090909091
A6: =IFNA(VLOOKUP(B6,Sprites!$A$2:$B$1200,2,FALSE),"") | B6: Zorua H | C6: 330 | D6: Level 30 | E6: 510 | F6: 5 | G6: Ghost | H6: 8 | I6: 5
A7: =IFNA(VLOOKUP(B7,Sprites!$A$2:$B$1200,2,FALSE),"") | B7: Eevee | C7: 325 | D7: Roguestone | E7: 525 | F7: 6 | H7: 7 | I7: 6
A8: =IFNA(VLOOKUP(B8,Sprites!$A$2:$B$1200,2,FALSE),"") | B8: Bidoof | C8: 250 | D8: Level 15 | E8: 410 | F8: 2 | H8: 7 | I8: 7
A9: =IFNA(VLOOKUP(B9,Sprites!$A$2:$B$1200,2,FALSE),"") | B9: Lickitung | C9: 385 | D9: Level 33 | E9: 515 | F9: 4 | H9: 7 | I9: 8
A10: =IFNA(VLOOKUP(B10,Sprites!$A$2:$B$1200,2,FALSE),"") | B10: Litleo | C10: 369 | D10: Level 35 | E10: 507 | F10: 6 | G10: Fire | H10: 7 | I10: 9
A11: =IFNA(VLOOKUP(B11,Sprites!$A$2:$B$1200,2,FALSE),"") | B11: Buneary | C11: 350 | D11: Friendship | E11: 480 | F11: 7 | H11: 7 | I11: 10
A12: =IFNA(VLOOKUP(B12,Sprites!$A$2:$B$1200,2,FALSE),"") | B12: Porygon | C12: 395 | D12: Roguestone | E12: 515 | F12: 9 | H12: 6 | I12: 11
A13: =IFNA(VLOOKUP(B13,Sprites!$A$2:$B$1200,2,FALSE),"") | B13: Sentret | C13: 215 | D13: Level 15 | E13: 415 | F13: 1 | H13: 6 | I13: 12
A14: =IFNA(VLOOKUP(B14,Sprites!$A$2:$B$1200,2,FALSE),"") | B14: Stufful | C14: 340 | D14: Level 27 | E14: 500 | F14: 4 | G14: Fighting | H14: 6 | I14: 13
A15: =IFNA(VLOOKUP(B15,Sprites!$A$2:$B$1200,2,FALSE),"") | B15: Lillipup | C15: 275 | D15: Level 16 | E15: 370 | F15: 1 | H15: 6 | I15: 14
A16: =IFNA(VLOOKUP(B16,Sprites!$A$2:$B$1200,2,FALSE),"") | B16: Deerling | C16: 335 | D16: Level 34 | E16: 475 | F16: 7 | G16: Grass | H16: 6 | I16: 15
A17: =IFNA(VLOOKUP(B17,Sprites!$A$2:$B$1200,2,FALSE),"") | B17: Teddiursa | C17: 330 | D17: Level 30 | E17: 500 | F17: 5 | H17: 5 | I17: 16
